# Issue 34959: Fix doctest in sage/schemes/elliptic_curves/ell_number_field.py

archive/issues_034722.json:
```json
{
    "assignees": [],
    "body": "<div id=\"comment:0\"></div>\n\nA \"long\" annotation is missing in a doctest introduced in #34537, causing:\n\n```\nsage -t --random-seed=257591867899933130420640722238032668369 sage/schemes/elliptic_curves/ell_number_field.py\n**********************************************************************\nFile \"sage/schemes/elliptic_curves/ell_number_field.py\", line 2304, in sage.schemes.elliptic_curves.ell_number_field.EllipticCurve_number_field.gens\nFailed example:\n    P=gg[0]; P.order()\nException raised:\n    Traceback (most recent call last):\n      File \"/__w/sagetrac-mirror/sagetrac-mirror/src/sage/doctest/forker.py\", line 695, in _run\n        self.compile_and_execute(example, compiler, test.globs)\n      File \"/__w/sagetrac-mirror/sagetrac-mirror/src/sage/doctest/forker.py\", line 1093, in compile_and_execute\n        exec(compiled, globs)\n      File \"<doctest sage.schemes.elliptic_curves.ell_number_field.EllipticCurve_number_field.gens[7]>\", line 1, in <module>\n        P=gg[Integer(0)]; P.order()\n    NameError: name 'gg' is not defined\n```\n\nCC:  @dimpase\n\nComponent: **doctest coverage**\n\n_Issue created by migration from https://trac.sagemath.org/ticket/34959_\n\n",
    "created_at": "2023-01-30T07:09:02Z",
    "labels": [
        "https://github.com/sagemath/sage/labels/doctest%20coverage",
        "https://github.com/sagemath/sage/labels/p%3A%20critical%20/%202",
        "https://github.com/sagemath/sage/labels/bug"
    ],
    "milestone": "https://github.com/sagemath/sage/milestones/sage-9.8",
    "reactions": [],
    "repository": "https://github.com/sagemath/sage",
    "title": "Fix doctest in sage/schemes/elliptic_curves/ell_number_field.py",
    "type": "issue",
    "updated_at": "2023-01-30T07:09:02Z",
    "url": "https://github.com/sagemath/sage/issues/34959",
    "user": "https://github.com/mkoeppe"
}
```
<div id="comment:0"></div>

A "long" annotation is missing in a doctest introduced in #34537, causing:

```
sage -t --random-seed=257591867899933130420640722238032668369 sage/schemes/elliptic_curves/ell_number_field.py
**********************************************************************
File "sage/schemes/elliptic_curves/ell_number_field.py", line 2304, in sage.schemes.elliptic_curves.ell_number_field.EllipticCurve_number_field.gens
Failed example:
    P=gg[0]; P.order()
Exception raised:
    Traceback (most recent call last):
      File "/__w/sagetrac-mirror/sagetrac-mirror/src/sage/doctest/forker.py", line 695, in _run
        self.compile_and_execute(example, compiler, test.globs)
      File "/__w/sagetrac-mirror/sagetrac-mirror/src/sage/doctest/forker.py", line 1093, in compile_and_execute
        exec(compiled, globs)
      File "<doctest sage.schemes.elliptic_curves.ell_number_field.EllipticCurve_number_field.gens[7]>", line 1, in <module>
        P=gg[Integer(0)]; P.order()
    NameError: name 'gg' is not defined
```

CC:  @dimpase

Component: **doctest coverage**

_Issue created by migration from https://trac.sagemath.org/ticket/34959_





---

archive/issue_events_473209.json:
```json
{
    "actor": "https://github.com/mkoeppe",
    "created_at": "2023-01-30T07:09:02Z",
    "event": "milestoned",
    "issue": "https://github.com/sagemath/sage/issues/34959",
    "milestone_number": null,
    "milestone_title": "sage-9.8",
    "type": "issue_event",
    "url": "https://github.com/sagemath/sage/issues/34959#event-473209"
}
```



---

archive/issue_events_473210.json:
```json
{
    "actor": "https://github.com/mkoeppe",
    "created_at": "2023-01-30T07:09:02Z",
    "event": "labeled",
    "issue": "https://github.com/sagemath/sage/issues/34959",
    "label": "https://github.com/sagemath/sage/labels/doctest%20coverage",
    "label_color": "696969",
    "label_name": "doctest coverage",
    "label_text_color": "ffffff",
    "type": "issue_event",
    "url": "https://github.com/sagemath/sage/issues/34959#event-473210"
}
```



---

archive/issue_events_473211.json:
```json
{
    "actor": "https://github.com/mkoeppe",
    "created_at": "2023-01-30T07:09:02Z",
    "event": "labeled",
    "issue": "https://github.com/sagemath/sage/issues/34959",
    "label": "https://github.com/sagemath/sage/labels/p%3A%20critical%20/%202",
    "label_color": "ff7700",
    "label_name": "p: critical / 2",
    "label_text_color": "ffffff",
    "type": "issue_event",
    "url": "https://github.com/sagemath/sage/issues/34959#event-473211"
}
```



---

archive/issue_events_473212.json:
```json
{
    "actor": "https://github.com/mkoeppe",
    "created_at": "2023-01-30T07:09:02Z",
    "event": "labeled",
    "issue": "https://github.com/sagemath/sage/issues/34959",
    "label": "https://github.com/sagemath/sage/labels/bug",
    "label_color": "d73a4a",
    "label_name": "bug",
    "label_text_color": "ffffff",
    "type": "issue_event",
    "url": "https://github.com/sagemath/sage/issues/34959#event-473212"
}
```
