# Issue 2583: Sage 2.11.a0: doctest failure in plot.py due to #2580

archive/issues_002583.json:
```json
{
    "body": "\n```\nsage -t -long devel/sage/sage/plot/plot.py\n----------------------------------------------------------------------\nTotal time for all tests: 965.6 seconds\nmabshoff@sage:/scratch/mabshoff/release-cycle/sage-2.11.alpha0$ ./sage -t -long devel/sage/sage/plot/plot.py\nsage -t -long devel/sage-main/sage/plot/plot.py             **********************************************************************\nFile \"plot.py\", line 3860:\n    sage: networkx_plot(C._nxg, pos=C.get_pos(), edge_colors=edge_colors, vertex_labels=False, vertex_size=0)\nException raised:\n    Traceback (most recent call last):\n      File \"/scratch/mabshoff/release-cycle/sage-2.11.alpha0/local/lib/python2.5/doctest.py\", line 1212, in __run\n        compileflags, 1) in test.globs\n      File \"<doctest __main__.example_118[17]>\", line 1, in <module>\n        networkx_plot(C._nxg, pos=C.get_pos(), edge_colors=edge_colors, vertex_labels=False, vertex_size=Integer(0))###line 3860:\n    sage: networkx_plot(C._nxg, pos=C.get_pos(), edge_colors=edge_colors, vertex_labels=False, vertex_size=0)\n    AttributeError: 'Graph' object has no attribute '_nxg'\n**********************************************************************\n1 items had failures:\n   1 of  18 in __main__.example_118\n***Test Failed*** 1 failures.\nFor whitespace errors, see the file .doctest_plot.py\n         [68.5 s]\nexit code: 256\n```\n\nAs a reminder: Ye Shall doctest the all of Sage before submitting any patch that changes fundamental things.\n\nCheers,\n\nMichael\n\n**Assignee:** @rlmill\n\nIssue created by migration from https://trac.sagemath.org/ticket/2583\n\n",
    "closed_at": "2008-03-19T13:29:34Z",
    "created_at": "2008-03-18T11:27:43Z",
    "labels": [
        "component: graph theory",
        "blocker",
        "bug"
    ],
    "milestone": "https://github.com/sagemath/sage/milestones/sage-2.11",
    "title": "Sage 2.11.a0: doctest failure in plot.py due to #2580",
    "type": "issue",
    "url": "https://github.com/sagemath/sage/issues/2583",
    "user": "https://trac.sagemath.org/admin/accounts/users/mabshoff"
}
```

```
sage -t -long devel/sage/sage/plot/plot.py
----------------------------------------------------------------------
Total time for all tests: 965.6 seconds
mabshoff@sage:/scratch/mabshoff/release-cycle/sage-2.11.alpha0$ ./sage -t -long devel/sage/sage/plot/plot.py
sage -t -long devel/sage-main/sage/plot/plot.py             **********************************************************************
File "plot.py", line 3860:
    sage: networkx_plot(C._nxg, pos=C.get_pos(), edge_colors=edge_colors, vertex_labels=False, vertex_size=0)
Exception raised:
    Traceback (most recent call last):
      File "/scratch/mabshoff/release-cycle/sage-2.11.alpha0/local/lib/python2.5/doctest.py", line 1212, in __run
        compileflags, 1) in test.globs
      File "<doctest __main__.example_118[17]>", line 1, in <module>
        networkx_plot(C._nxg, pos=C.get_pos(), edge_colors=edge_colors, vertex_labels=False, vertex_size=Integer(0))###line 3860:
    sage: networkx_plot(C._nxg, pos=C.get_pos(), edge_colors=edge_colors, vertex_labels=False, vertex_size=0)
    AttributeError: 'Graph' object has no attribute '_nxg'
**********************************************************************
1 items had failures:
   1 of  18 in __main__.example_118
***Test Failed*** 1 failures.
For whitespace errors, see the file .doctest_plot.py
         [68.5 s]
exit code: 256
```

As a reminder: Ye Shall doctest the all of Sage before submitting any patch that changes fundamental things.

Cheers,

Michael

**Assignee:** @rlmill

Issue created by migration from https://trac.sagemath.org/ticket/2583





---

archive/attachments_002455.json:
```json
{
    "asset_content_type": "application/octet-stream",
    "asset_name": "2583.patch",
    "asset_url": "tarball://root/attachments/ticket2583/2583.patch",
    "created_at": "2008-03-18T13:32:20Z",
    "issue": "https://github.com/sagemath/sage/issues/2583",
    "type": "attachment",
    "url": "https://github.com/sagemath/sage/files/ticket2583/2583.patch",
    "user": "https://github.com/rlmill"
}
```



---

archive/issue_comments_014011.json:
```json
{
    "body": "**Attachment:** [2583.patch](https://github.com/sagemath/sage/files/ticket2583/2583.patch)",
    "created_at": "2008-03-18T13:32:20Z",
    "issue": "https://github.com/sagemath/sage/issues/2583",
    "type": "issue_comment",
    "url": "https://github.com/sagemath/sage/issues/2583#issuecomment-14011",
    "user": "https://github.com/rlmill"
}
```

**Attachment:** [2583.patch](https://github.com/sagemath/sage/files/ticket2583/2583.patch)



---

archive/issue_events_013354.json:
```json
{
    "actor": "https://github.com/rlmill",
    "created_at": "2008-03-19T00:14:26Z",
    "event": "labeled",
    "issue": "https://github.com/sagemath/sage/issues/2583",
    "label": "needs review",
    "type": "issue_event",
    "url": "https://github.com/sagemath/sage/issues/2583#event-13354"
}
```



---

archive/issue_events_013355.json:
```json
{
    "actor": "https://trac.sagemath.org/admin/accounts/users/mabshoff",
    "created_at": "2008-03-19T00:38:54Z",
    "event": "unlabeled",
    "issue": "https://github.com/sagemath/sage/issues/2583",
    "label": "needs review",
    "type": "issue_event",
    "url": "https://github.com/sagemath/sage/issues/2583#event-13355"
}
```



---

archive/issue_events_013356.json:
```json
{
    "actor": "https://trac.sagemath.org/admin/accounts/users/mabshoff",
    "created_at": "2008-03-19T00:38:54Z",
    "event": "labeled",
    "issue": "https://github.com/sagemath/sage/issues/2583",
    "label": "positive review",
    "type": "issue_event",
    "url": "https://github.com/sagemath/sage/issues/2583#event-13356"
}
```



---

archive/issue_comments_014012.json:
```json
{
    "body": "<a id='comment:2'></a>\nPatch looks good to me and fixes the issue.\n\nCheers,\n\nMichael",
    "created_at": "2008-03-19T00:38:54Z",
    "issue": "https://github.com/sagemath/sage/issues/2583",
    "type": "issue_comment",
    "url": "https://github.com/sagemath/sage/issues/2583#issuecomment-14012",
    "user": "https://trac.sagemath.org/admin/accounts/users/mabshoff"
}
```

<a id='comment:2'></a>
Patch looks good to me and fixes the issue.

Cheers,

Michael



---

archive/issue_comments_014013.json:
```json
{
    "body": "<a id='comment:3'></a>\nMerged in Sage 2.11.alpha0",
    "created_at": "2008-03-19T00:39:38Z",
    "issue": "https://github.com/sagemath/sage/issues/2583",
    "type": "issue_comment",
    "url": "https://github.com/sagemath/sage/issues/2583#issuecomment-14013",
    "user": "https://trac.sagemath.org/admin/accounts/users/mabshoff"
}
```

<a id='comment:3'></a>
Merged in Sage 2.11.alpha0



---

archive/issue_events_013357.json:
```json
{
    "actor": "https://trac.sagemath.org/admin/accounts/users/mabshoff",
    "created_at": "2008-03-19T00:39:38Z",
    "event": "unlabeled",
    "issue": "https://github.com/sagemath/sage/issues/2583",
    "label": "positive review",
    "type": "issue_event",
    "url": "https://github.com/sagemath/sage/issues/2583#event-13357"
}
```



---

archive/issue_events_013358.json:
```json
{
    "actor": "https://trac.sagemath.org/admin/accounts/users/mabshoff",
    "created_at": "2008-03-19T00:39:38Z",
    "event": "closed",
    "issue": "https://github.com/sagemath/sage/issues/2583",
    "type": "issue_event",
    "url": "https://github.com/sagemath/sage/issues/2583#event-13358"
}
```



---

archive/issue_events_013359.json:
```json
{
    "actor": "https://trac.sagemath.org/admin/accounts/users/mabshoff",
    "created_at": "2008-03-19T10:13:22Z",
    "event": "renamed",
    "issue": "https://github.com/sagemath/sage/issues/2583",
    "rename": {
        "from": "Sage 2.11.a0: doctest failure in plot.py due to #2580",
        "to": "[reopened] Sage 2.11.a0: doctest failure in plot.py due to #2580"
    },
    "type": "issue_event",
    "url": "https://github.com/sagemath/sage/issues/2583#event-13359"
}
```



---

archive/issue_events_013360.json:
```json
{
    "actor": "https://trac.sagemath.org/admin/accounts/users/mabshoff",
    "created_at": "2008-03-19T10:13:22Z",
    "event": "labeled",
    "issue": "https://github.com/sagemath/sage/issues/2583",
    "label": "positive review",
    "type": "issue_event",
    "url": "https://github.com/sagemath/sage/issues/2583#event-13360"
}
```



---

archive/issue_events_013361.json:
```json
{
    "actor": "https://trac.sagemath.org/admin/accounts/users/mabshoff",
    "created_at": "2008-03-19T10:13:22Z",
    "event": "unlabeled",
    "issue": "https://github.com/sagemath/sage/issues/2583",
    "label": "positive review",
    "type": "issue_event",
    "url": "https://github.com/sagemath/sage/issues/2583#event-13361"
}
```



---

archive/issue_comments_014014.json:
```json
{
    "body": "<a id='comment:4'></a>\nBut it causes a new doctest failure:\n\n```\nmabshoff@sage:/scratch/mabshoff/release-cycle/sage-2.11.alpha0$ ./sage -t -long devel/sage/sage/plot/plot.py\nsage -t -long devel/sage-main/sage/plot/plot.py             File \"plot.py\", line 3513:\n    sage: plot(x^(1/3), (x,-1,1))\nExpected nothing\nGot:\n    WARNING: When plotting, failed to evaluate function at 99 points.\n    Last error message: 'negative number cannot be raised to a fractional power'\n    <BLANKLINE>\n**********************************************************************\n1 items had failures:\n   2 of  28 in __main__.example_111\n***Test Failed*** 2 failures.\nFor whitespace errors, see the file .doctest_plot.py\n         [70.3 s]\nexit code: 256\n\n----------------------------------------------------------------------\nThe following tests failed:\n\n```\nso I am reopening it.\n\nCheers,\n\nMichael",
    "created_at": "2008-03-19T10:13:22Z",
    "issue": "https://github.com/sagemath/sage/issues/2583",
    "type": "issue_comment",
    "url": "https://github.com/sagemath/sage/issues/2583#issuecomment-14014",
    "user": "https://trac.sagemath.org/admin/accounts/users/mabshoff"
}
```

<a id='comment:4'></a>
But it causes a new doctest failure:

```
mabshoff@sage:/scratch/mabshoff/release-cycle/sage-2.11.alpha0$ ./sage -t -long devel/sage/sage/plot/plot.py
sage -t -long devel/sage-main/sage/plot/plot.py             File "plot.py", line 3513:
    sage: plot(x^(1/3), (x,-1,1))
Expected nothing
Got:
    WARNING: When plotting, failed to evaluate function at 99 points.
    Last error message: 'negative number cannot be raised to a fractional power'
    <BLANKLINE>
**********************************************************************
1 items had failures:
   2 of  28 in __main__.example_111
***Test Failed*** 2 failures.
For whitespace errors, see the file .doctest_plot.py
         [70.3 s]
exit code: 256

----------------------------------------------------------------------
The following tests failed:

```
so I am reopening it.

Cheers,

Michael



---

archive/issue_comments_014015.json:
```json
{
    "body": "<a id='comment:5'></a>\nThis is unrelated to this patch and hence we will close it and open another ticket for it.\n\nCheers,\n\nMichael",
    "created_at": "2008-03-19T13:29:34Z",
    "issue": "https://github.com/sagemath/sage/issues/2583",
    "type": "issue_comment",
    "url": "https://github.com/sagemath/sage/issues/2583#issuecomment-14015",
    "user": "https://trac.sagemath.org/admin/accounts/users/mabshoff"
}
```

<a id='comment:5'></a>
This is unrelated to this patch and hence we will close it and open another ticket for it.

Cheers,

Michael



---

archive/issue_events_013362.json:
```json
{
    "actor": "https://trac.sagemath.org/admin/accounts/users/mabshoff",
    "created_at": "2008-03-19T13:29:34Z",
    "event": "closed",
    "issue": "https://github.com/sagemath/sage/issues/2583",
    "type": "issue_event",
    "url": "https://github.com/sagemath/sage/issues/2583#event-13362"
}
```



---

archive/issue_events_013363.json:
```json
{
    "actor": "https://trac.sagemath.org/admin/accounts/users/mabshoff",
    "created_at": "2008-03-19T13:29:46Z",
    "event": "renamed",
    "issue": "https://github.com/sagemath/sage/issues/2583",
    "rename": {
        "from": "[reopened] Sage 2.11.a0: doctest failure in plot.py due to #2580",
        "to": "Sage 2.11.a0: doctest failure in plot.py due to #2580"
    },
    "type": "issue_event",
    "url": "https://github.com/sagemath/sage/issues/2583#event-13363"
}
```



---

archive/issue_events_013364.json:
```json
{
    "actor": "https://trac.sagemath.org/admin/accounts/users/mabshoff",
    "created_at": "2008-03-19T13:29:46Z",
    "event": "labeled",
    "issue": "https://github.com/sagemath/sage/issues/2583",
    "label": "positive review",
    "type": "issue_event",
    "url": "https://github.com/sagemath/sage/issues/2583#event-13364"
}
```
